<?xml version="1.0"?>
<sdf version="1.7">
  <model name="kpbot">
    <!-- Base Link -->
    <link name="base_link">
      <visual name="base_visual">
        <geometry>
          <mesh>
            <uri>model://meshes/base.stl</uri>
            <scale>1 1 1</scale>
          </mesh>
        </geometry>
        <origin xyz="0 0 0" rpy="0 0 0" />
        <material>
          <script>
            <uri>file://media/materials/scripts/gazebo.material</uri>
            <name>Gazebo/Blue</name>
          </script>
        </material>
      </visual>
      <collision name="base_collision">
        <geometry>
          <box>
            <size>0.25 0.25 0</size>
          </box>
        </geometry>
        <origin xyz="0 0 0" rpy="0 0 0" />
      </collision>
      <inertial>
        <mass>1.0</mass> <!-- Increased mass for stability -->
        <inertia>
          <ixx>0.041667</ixx> <!-- Updated for 4 kg mass -->
          <iyy>0.041667</iyy>
          <izz>0.020833</izz>
          <ixy>0</ixy>
          <ixz>0</ixz>
          <iyz>0</iyz>
        </inertia>
        <pose>0 0 0 0 0 0</pose> <!-- Lowered CoM -->
      </inertial>
    </link>

    <!-- Back Right Wheel -->
    <link name="back_right_wheel_link">
      <visual name="back_right_wheel_visual">
        <geometry>
          <mesh>
            <uri>model://meshes/wheel1.stl</uri>
            <scale>1 1 1</scale>
          </mesh>
        </geometry>
        <origin xyz="-0.07 0.141 -0.03" rpy="0 0 0" />
        <material>
          <script>
            <uri>file://media/materials/scripts/gazebo.material</uri>
            <name>Gazebo/Red</name>
          </script>
        </material>
      </visual>
      <collision name="back_right_wheel_collision">
        <geometry>
          <cylinder>
            <radius>0.035</radius>
            <length>0.025</length>
          </cylinder>
        </geometry>
        <origin xyz="-0.064 0.141 -0.035" rpy="1.57 0 0" />
        <surface>
          <friction>
            <ode>
              <mu>1.0</mu> <!-- Increased friction -->
              <mu2>1.0</mu2>
            </ode>
          </friction>
        </surface>
      </collision>
      <inertial>
        <mass>0.2</mass>
        <inertia>
          <ixx>0.000306</ixx>
          <iyy>0.000613</iyy>
          <izz>0.000306</izz>
          <ixy>0</ixy>
          <ixz>0</ixz>
          <iyz>0</iyz>
        </inertia>
      </inertial>
    </link>

    <!-- Front Right Wheel -->
    <link name="front_right_wheel_link">
      <visual name="front_right_wheel_visual">
        <geometry>
          <mesh>
            <uri>model://meshes/wheel2.stl</uri>
            <scale>1 1 1</scale>
          </mesh>
        </geometry>
        <origin xyz="0.092 0.141 -0.035" rpy="0 0 0" />
        <material>
          <script>
            <uri>file://media/materials/scripts/gazebo.material</uri>
            <name>Gazebo/Red</name>
          </script>
        </material>
      </visual>
      <collision name="front_right_wheel_collision">
        <geometry>
          <cylinder>
            <radius>0.035</radius>
            <length>0.025</length>
          </cylinder>
        </geometry>
        <origin xyz="0.087 0.141 -0.03" rpy="1.57 0 0" />
        <surface>
          <friction>
            <ode>
              <mu>1.0</mu> <!-- Increased friction -->
              <mu2>1.0</mu2>
            </ode>
          </friction>
        </surface>
      </collision>
      <inertial>
        <mass>0.2</mass>
        <inertia>
          <ixx>0.000306</ixx>
          <iyy>0.000613</iyy>
          <izz>0.000306</izz>
          <ixy>0</ixy>
          <ixz>0</ixz>
          <iyz>0</iyz>
        </inertia>
      </inertial>
    </link>

    <!-- Back Left Wheel -->
    <link name="back_left_wheel_link">
      <visual name="back_left_wheel_visual">
        <geometry>
          <mesh>
            <uri>model://meshes/wheel3.stl</uri>
            <scale>1 1 1</scale>
          </mesh>
        </geometry>
        <origin xyz="-0.07 -0.15 -0.03" rpy="0 0 0" />
        <material>
          <script>
            <uri>file://media/materials/scripts/gazebo.material</uri>
            <name>Gazebo/Red</name>
          </script>
        </material>
      </visual>
      <collision name="back_left_wheel_collision">
        <geometry>
          <cylinder>
            <radius>0.035</radius>
            <length>0.025</length>
          </cylinder>
        </geometry>
        <origin xyz="-0.064 -0.15 -0.035" rpy="1.57 0 0" />
        <surface>
          <friction>
            <ode>
              <mu>1.0</mu> <!-- Increased friction -->
              <mu2>1.0</mu2>
            </ode>
          </friction>
        </surface>
      </collision>
      <inertial>
        <mass>0.2</mass>
        <inertia>
          <ixx>0.000306</ixx>
          <iyy>0.000613</iyy>
          <izz>0.000306</izz>
          <ixy>0</ixy>
          <ixz>0</ixz>
          <iyz>0</iyz>
        </inertia>
      </inertial>
    </link>

    <!-- Front Left Wheel -->
    <link name="front_left_wheel_link">
      <visual name="front_left_wheel_visual">
        <geometry>
          <mesh>
            <uri>model://meshes/wheel4.stl</uri>
            <scale>1 1 1</scale>
          </mesh>
        </geometry>
        <origin xyz="0.092 -0.15 -0.035" rpy="0 0 0" />
        <material>
          <script>
            <uri>file://media/materials/scripts/gazebo.material</uri>
            <name>Gazebo/Red</name>
          </script>
        </material>
      </visual>
      <collision name="front_left_wheel_collision">
        <geometry>
          <cylinder>
            <radius>0.035</radius>
            <length>0.025</length>
          </cylinder>
        </geometry>
        <origin xyz="0.087 -0.15 -0.03" rpy="1.57 0 0" />
        <surface>
          <friction>
            <ode>
              <mu>1.0</mu> <!-- Increased friction -->
              <mu2>1.0</mu2>
            </ode>
          </friction>
        </surface>
      </collision>
      <inertial>
        <mass>0.2</mass>
        <inertia>
          <ixx>0.000306</ixx>
          <iyy>0.000613</iyy>
          <izz>0.000306</izz>
          <ixy>0</ixy>
          <ixz>0</ixz>
          <iyz>0</iyz>
        </inertia>
      </inertial>
    </link>

    <!-- Joints -->
    <joint name="base_joint" type="fixed">
        <parent>base_footprint</parent>
        <child>base_link</child>
        <pose>0 0 0.3 0 0 0</pose>

    </joint>

    <joint name="back_right_joint" type="revolute">
      <parent>base_link</parent>
      <child>back_right_wheel_link</child>
      <pose>0.064 -0.141 0.035 0 0 0</pose>
      <axis>
        <xyz>0 1 0</xyz>
      </axis>
    </joint>

    <joint name="front_right_joint" type="revolute">
      <parent>base_link</parent>
      <child>front_right_wheel_link</child>
      <pose>-0.092 -0.141 0.035 0 0 0</pose>
      <axis>
        <xyz>0 1 0</xyz>
      </axis>
    </joint>

    <joint name="back_left_joint" type="revolute">
      <parent>base_link</parent>
      <child>back_left_wheel_link</child>
      <pose>0.064 0.15 0.035 0 0 0</pose>
      <axis>
        <xyz>0 1 0</xyz>
      </axis>
    </joint>

    <joint name="front_left_joint" type="revolute">
      <parent>base_link</parent>
      <child>front_left_wheel_link</child>
      <pose>-0.092 0.15 0.035 0 0 0</pose>
      <axis>
        <xyz>0 1 0</xyz>
      </axis>
    </joint>

    <!-- Plugins -->
    <plugin name="diff_drive_controller" filename="libgazebo_ros_diff_drive.so">
      <ros>
        <namespace>/</namespace>
        <remapping>cmd_vel:=/cmd_vel</remapping>
        <remapping>odom:=/odom</remapping>
      </ros>
      <update_rate>20</update_rate>
      <num_wheel_pairs>2</num_wheel_pairs>

      <left_joint>front_right_joint</left_joint>
      <left_joint>back_right_joint</left_joint>
      <right_joint>front_left_joint</right_joint>
      <right_joint>back_left_joint</right_joint>

      <wheel_separation>0.3</wheel_separation>
      <wheel_diameter>0.07</wheel_diameter>
      <odom_frame>odom</odom_frame>
      <odom_topic>odom</odom_topic>
      <base_frame>base_link</base_frame>
      <publish_odom>true</publish_odom>
      <publish_wheel_tf>false</publish_wheel_tf>
      <publish_wheel_joint_state>false</publish_wheel_joint_state>
    </plugin>

    <plugin name="kpbot_joint_state" filename="libgazebo_ros_joint_state_publisher.so">
      <ros>
        <remapping>~/out:=joint_states</remapping>
      </ros>
      <update_rate>30</update_rate>
      <joint_name>back_right_joint</joint_name>
      <joint_name>front_right_joint</joint_name>
      <joint_name>back_left_joint</joint_name>
      <joint_name>front_left_joint</joint_name>
    </plugin>
  </model>
</sdf>